Workbook
Name Slicer_Year: #N/A

Sheet Cover Page

Sheet  Summary
B1: Scenario: | H1: The Peak&Light Restaurant | K1: Last Updated: | L1: 26/03/2025
C3: Company Name: | F3: The Peak&Light Restaurant
C4: Sector: | E4: Hospitality
C6: Equity Investment | G6: =Workings!K90 -> 17537693
C7: Enterprise Value | G7: =Valuation!I21 -> 2.3302391e+08
C8: Equity Valuation | G8: =Valuation!I41 -> 95496030
G10: 2025 | H10: =G10+1 -> 2026 | I10: =H10+1 -> 2027 | J10: =I10+1 -> 2028 | K10: =J10+1 -> 2029
C11: Income Statement
D12: Revenue | G12: ='Income Statement'!I4 -> 56448000 | H12: ='Income Statement'!J4 -> 64610381 | I12: ='Income Statement'!K4 -> 73655834 | J12: ='Income Statement'!L4 -> 83967651 | K12: ='Income Statement'!M4 -> 95723122
D13: Cost Of sales | G13: =-'Income Statement'!I6 -> 16934400 | H13: =-'Income Statement'!J6 -> 19383114 | I13: =-'Income Statement'!K6 -> 22096750 | J13: =-'Income Statement'!L6 -> 25190295 | K13: =-'Income Statement'!M6 -> 28716937
D14: Gross Profit | G14: ='Income Statement'!I8 -> 39513600 | H14: ='Income Statement'!J8 -> 45227267 | I14: ='Income Statement'!K8 -> 51559084 | J14: ='Income Statement'!L8 -> 58777356 | K14: ='Income Statement'!M8 -> 67006185
D15: Operating Expenses | G15: =-'Income Statement'!I10 -> 12304480 | H15: =-'Income Statement'!J10 -> 14386104 | I15: =-'Income Statement'!K10 -> 14476558 | J15: =-'Income Statement'!L10 -> 14579677 | K15: =-'Income Statement'!M10 -> 14697231
D16: Operation Income | G16: ='Income Statement'!I12 -> 27209120 | H16: ='Income Statement'!J12 -> 30841163 | I16: ='Income Statement'!K12 -> 37082526 | J16: ='Income Statement'!L12 -> 44197679 | K16: ='Income Statement'!M12 -> 52308954
D17: Profit Before Tax | G17: ='Income Statement'!I16 -> 25104320 | H17: ='Income Statement'!J16 -> 28736363 | I17: ='Income Statement'!K16 -> 34977726 | J17: ='Income Statement'!L16 -> 41922879 | K17: ='Income Statement'!M16 -> 50034154
D18: Net Profit | G18: ='Income Statement'!I18 -> 25104320 | H18: ='Income Statement'!J18 -> 28736363 | I18: ='Income Statement'!K18 -> 34977726 | J18: ='Income Statement'!L18 -> 41922879 | K18: ='Income Statement'!M18 -> 50034154
C20: Balance Sheet
D21: Non-Current Asset | G21: ='Balance Sheet'!K9 -> 7895200 | H21: ='Balance Sheet'!L9 -> 5790400 | I21: ='Balance Sheet'!M9 -> 3685600 | J21: ='Balance Sheet'!N9 -> 2260800 | K21: ='Balance Sheet'!O9 -> -14000
D22: Current Asset | G22: ='Balance Sheet'!K14 -> 34982013 | H22: ='Balance Sheet'!L14 -> 59581106 | I22: ='Balance Sheet'!M14 -> 89517230 | J22: ='Balance Sheet'!N14 -> 1.2416344e+08 | K22: ='Balance Sheet'!O14 -> 1.6604066e+08
D23: Total Asset | G23: ='Balance Sheet'!K16 -> 42877213 | H23: ='Balance Sheet'!L16 -> 65371506 | I23: ='Balance Sheet'!M16 -> 93202830 | J23: ='Balance Sheet'!N16 -> 1.2642424e+08 | K23: ='Balance Sheet'!O16 -> 1.6602666e+08
D24: Total Net Asset | G24: ='Balance Sheet'!K16-'Balance Sheet'!K30 -> 36365933 | H24: ='Balance Sheet'!L16-'Balance Sheet'!L30 -> 57918205 | I24: ='Balance Sheet'!M16-'Balance Sheet'!M30 -> 84151500 | J24: ='Balance Sheet'!N16-'Balance Sheet'!N30 -> 1.1559366e+08 | K24: ='Balance Sheet'!O16-'Balance Sheet'!O30 -> 1.5311927e+08
C26: Total Equity
D27: Current Liabilities | G27: ='Balance Sheet'!K28 -> 6511280 | H27: ='Balance Sheet'!L28 -> 7453300.6 | I27: ='Balance Sheet'!M28 -> 9051330.7 | J27: ='Balance Sheet'!N28 -> 10830585 | K27: ='Balance Sheet'!O28 -> 12907385
D28: Total Equity and Liabilities | G28: ='Balance Sheet'!K32 -> 42877213 | H28: ='Balance Sheet'!L32 -> 65371506 | I28: ='Balance Sheet'!M32 -> 93202830 | J28: ='Balance Sheet'!N32 -> 1.2642424e+08 | K28: ='Balance Sheet'!O32 -> 1.6602666e+08
C30: Cash Flow Statement
D31: Cash Flow from Operating Activities | G31: =Cashflow!J14 -> 21517280 | H31: =Cashflow!K14 -> 30018123 | I31: =Cashflow!L14 -> 36170442 | J31: =Cashflow!M14 -> 43157904 | K31: =Cashflow!N14 -> 51123611
D32: Cash Flow From Investing Activities | G32: =Cashflow!J19 -> -10000000 | H32: =Cashflow!K19 -> 0 | I32: =Cashflow!L19 -> 0 | J32: =Cashflow!M19 -> -850000 | K32: =Cashflow!N19 -> 0
D33: Cash Flow From Financing Activities | G33: =Cashflow!J26 -> 17537693 | H33: =Cashflow!K26 -> -6276080 | I33: =Cashflow!L26 -> -7184090.7 | J33: =Cashflow!M26 -> -8744431.4 | K33: =Cashflow!N26 -> -10480720
D34: Net Cash Flow | G34: =Cashflow!J30 -> 29054973 | H34: =Cashflow!K30 -> 52797016 | I34: =Cashflow!L30 -> 81783368 | J34: =Cashflow!M30 -> 1.1534684e+08 | K34: =Cashflow!N30 -> 1.5598973e+08
D35: Free Cash Flow From Firm | G35: =Valuation!I11 -> 31517280 | H35: =Valuation!J11 -> 30018123 | I35: =Valuation!K11 -> 36170442 | J35: =Valuation!L11 -> 44007904 | K35: =Valuation!M11 -> 51123611
C37: Financial Ratios
D38: Gross Profit Margin | G38: ='Financial Ratios'!J5 -> 0.7 | H38: ='Financial Ratios'!K5 -> 0.7 | I38: ='Financial Ratios'!L5 -> 0.7 | J38: ='Financial Ratios'!M5 -> 0.7 | K38: ='Financial Ratios'!N5 -> 0.7
D39: Operating Profit Margin | G39: ='Financial Ratios'!J6 -> 0.48202098 | H39: ='Financial Ratios'!K6 -> 0.47734067 | I39: ='Financial Ratios'!L6 -> 0.50345673 | J39: ='Financial Ratios'!M6 -> 0.52636555 | K39: ='Financial Ratios'!N6 -> 0.54646101
D40: Net Profit Margin | G40: ='Financial Ratios'!J7 -> 0.44473356 | H40: ='Financial Ratios'!K7 -> 0.44476387 | I40: ='Financial Ratios'!L7 -> 0.47488058 | J40: ='Financial Ratios'!M7 -> 0.49927417 | K40: ='Financial Ratios'!N7 -> 0.52269664
D41: Return On Equity | G41: ='Financial Ratios'!J9 -> 0.69032519 | H41: ='Financial Ratios'!K9 -> 0.49615423 | I41: ='Financial Ratios'!L9 -> 0.41565184 | J41: ='Financial Ratios'!M9 -> 0.36267456 | K41: ='Financial Ratios'!N9 -> 0.32676588
D42: Return On Asset | G42: ='Financial Ratios'!J10 -> 0.58549327 | H42: ='Financial Ratios'!K10 -> 0.43958545 | I42: ='Financial Ratios'!L10 -> 0.37528609 | J42: ='Financial Ratios'!M10 -> 0.33160474 | K42: ='Financial Ratios'!N10 -> 0.30136217
D43: Equity Ratio | G43: ='Financial Ratios'!J18 -> 0.84814125 | H43: ='Financial Ratios'!K18 -> 0.88598548 | I43: ='Financial Ratios'!L18 -> 0.90288567 | J43: ='Financial Ratios'!M18 -> 0.91433142 | K43: ='Financial Ratios'!N18 -> 0.92225715
D44: Current Ratio | G44: ='Financial Ratios'!J13 -> 5.3725248 | H44: ='Financial Ratios'!K13 -> 7.9939223 | I44: ='Financial Ratios'!L13 -> 9.8899525 | J44: ='Financial Ratios'!M13 -> 11.464149 | K44: ='Financial Ratios'!N13 -> 12.864005
D45: Quick Ratio | G45: ='Financial Ratios'!J14 -> 4.4622522 | H45: ='Financial Ratios'!K14 -> 7.0837095 | I45: ='Financial Ratios'!L14 -> 9.0355076 | J45: ='Financial Ratios'!M14 -> 10.650103 | K45: ='Financial Ratios'!N14 -> 12.085309
D46: Cash Ratio | G46: ='Financial Ratios'!J15 -> 4.4622522 | H46: ='Financial Ratios'!K15 -> 7.0837095 | I46: ='Financial Ratios'!L15 -> 9.0355076 | J46: ='Financial Ratios'!M15 -> 10.650103 | K46: ='Financial Ratios'!N15 -> 12.085309

Sheet Table Of Content
G1: The Peak&Light Restaurant | L1: Last Updated: | N1: 26/03/2025
D2: TABLE OF CONTENT
B4: SN | C4: Details
B5: 1 | C5: Cover Page
B6: 2 | C6: Summary
B7: 3 | C7: Table Of Content
B8: 4 | C8: Dashboard
B9: 5 | C9: Input Data
B10: 6 | C10: Workings
B11: 7 | C11: Income Statement
B12: 8 | C12: Balance Sheet
B13: 9 | C13: Cashflow
B14: 10 | C14: Valuation
B15: 11 | C15: Financial Ratios
B16: 12 | C16: Dataset

Sheet Dashboard
I1: The Peak&Light Restaurant

Sheet Input Data
B1: Scenario: | D1: 2 | I1: The Peak&Light Restaurant | O1: Last Updated: | P1: 26/03/2025
D2: INPUT DATE (ASSUMPTION SHEET)
K4: 2024 | L4: =K4+1 -> 2025 | M4: =L4+1 -> 2026 | N4: =M4+1 -> 2027 | O4: =N4+1 -> 2028 | P4: =O4+1 -> 2029
C5: Days Of the Week | L5: 7 | M5: 7 | N5: 7 | O5: 7 | P5: 7
C6: Weeks | L6: 4 | M6: 4 | N6: 4 | O6: 4 | P6: 4
C7: Months | L7: 12 | M7: 12 | N7: 12 | O7: 12 | P7: 12
C8: Quarter | L8: 4 | M8: 4 | N8: 4 | O8: 4 | P8: 4
C9: Inflation Rate | L9: 0.1469 | M9: 0.1446 | N9: 0.14 | O9: 0.14 | P9: 0.14
D11: Credit Sales | E11: 0
D12: Inventory | E12: 0.35
D13: Credit Purchase | E13: 0.2
D14: Tax Rate | E14: 0
D15: Long Term Growth Rate | E15: 0.0384
D16: Margin | E16: 0.3
C18: Scenario
D19: Best Case | E19: 1.2
D20: Base Case | E20: 1
D21: Worst Case | E21: 0.5
C23: Revenue Assumption
D25: Food Sales | F25: NGN | G25: Daily | L25: 93000 | M25: =L25*(1+M9) -> 106447.8 | N25: =M25*(1+N9) -> 121350.49 | O25: =N25*(1+O9) -> 138339.56 | P25: =O25*(1+P9) -> 157707.1
D26: Drink sales | F26: NGN | G26: Daily | L26: 75000 | M26: =L26*(1+M9) -> 85845 | N26: =M26*(1+N9) -> 97863.3 | O26: =N26*(1+O9) -> 111564.16 | P26: =O26*(1+P9) -> 127183.14
C28: Cost Of Sales
D29: Direct Costs
E30: Food Ingredients | L30: 0.15 | M30: 0.15 | N30: 0.15 | O30: 0.15 | P30: 0.15
E31: Drinks Inventory | L31: 0.08 | M31: 0.08 | N31: 0.08 | O31: 0.08 | P31: 0.08
E32: Packaging | L32: 0.02 | M32: 0.02 | N32: 0.02 | O32: 0.02 | P32: 0.02
D34: Overheads | L34: 0.05 | M34: 0.05 | N34: 0.05 | O34: 0.05 | P34: 0.05
C36: Selling General And Admin EXP (SG&A)
D37: Cooking Gas | F37: NGN | G37: Per Month | L37: 150000 | M37: 150000 | N37: 150000 | O37: 150000 | P37: 150000
D38: Marketing and Promotion | F38: NGN | G38: Per Annum | L38: 0.01 | M38: 0.01 | N38: 0.01 | O38: 0.01 | P38: 0.01
D39: Rent | F39: NGN | G39: Per Annum | L39: 2000000 | M39: 2000000 | N39: 2000000 | O39: 2000000 | P39: 2000000
D40: Transportation | F40: NGN | G40: Per Month | L40: 10000 | M40: 10000 | N40: 10000 | O40: 10000 | P40: 10000
D41: Legal Fees | G41: Per Annum | L41: 100000 | M41: 100000 | N41: 100000 | O41: 100000 | P41: 100000
D42: Fuel/Diesel | F42: NGN | G42: Per Month | L42: 200000 | M42: 200000 | N42: 200000 | O42: 200000 | P42: 200000
D43: Others | F43: NGN | G43: Per Month | L43: 150000 | M43: 150000 | N43: 150000 | O43: 150000 | P43: 150000
C45: Staff Cost
D46: Manager | G46: Units | L46: 1 | M46: 1 | N46: 1 | O46: 1 | P46: 1
D47: Head Chef | G47: Units | L47: 1 | M47: 1 | N47: 1 | O47: 1 | P47: 1
D48: Cook | G48: Units | L48: 1 | M48: 1 | N48: 1 | O48: 1 | P48: 1
D49: Kitchen Assistant | G49: Units | L49: 1 | M49: 1 | N49: 1 | O49: 1 | P49: 1
...

Sheet Workings
B1: Scenario: | H1: The Peak&Light Restaurant | N1: Last Updated: | O1: 26/03/2025
F2: WORKINGS
J3: 2024 | K3: =J3+1 -> 2025 | L3: =K3+1 -> 2026 | M3: =L3+1 -> 2027 | N3: =M3+1 -> 2028 | O3: =N3+1 -> 2029
B4: Revenue
C6: Food Sales | K6: =INDEX('Input Data'!$E$19:$E$21,'Input Data'!$D$1)*('Input Data'!L25*'Input Data'!L5*'Input Data'!L6*'Input Data'!L7) -> 31248000 | L6: =INDEX('Input Data'!$E$19:$E$21,'Input Data'!$D$1)*('Input Data'!M25*'Input Data'!M5*'Input Data'!M6*'Input Data'!M7) -> 35766461 | M6: =INDEX('Input Data'!$E$19:$E$21,'Input Data'!$D$1)*('Input Data'!N25*'Input Data'!N5*'Input Data'!N6*'Input Data'!N7) -> 40773765 | N6: =INDEX('Input Data'!$E$19:$E$21,'Input Data'!$D$1)*('Input Data'!O25*'Input Data'!O5*'Input Data'!O6*'Input Data'!O7) -> 46482092 | O6: =INDEX('Input Data'!$E$19:$E$21,'Input Data'!$D$1)*('Input Data'!P25*'Input Data'!P5*'Input Data'!P6*'Input Data'!P7) -> 52989585
C7: Drink sales | K7: =INDEX('Input Data'!$E$19:$E$21,'Input Data'!$D$1)*('Input Data'!L26*'Input Data'!L5*'Input Data'!L6*'Input Data'!L7) -> 25200000 | L7: =INDEX('Input Data'!$E$19:$E$21,'Input Data'!$D$1)*('Input Data'!M26*'Input Data'!M5*'Input Data'!M6*'Input Data'!M7) -> 28843920 | M7: =INDEX('Input Data'!$E$19:$E$21,'Input Data'!$D$1)*('Input Data'!N26*'Input Data'!N5*'Input Data'!N6*'Input Data'!N7) -> 32882069 | N7: =INDEX('Input Data'!$E$19:$E$21,'Input Data'!$D$1)*('Input Data'!O26*'Input Data'!O5*'Input Data'!O6*'Input Data'!O7) -> 37485558 | O7: =INDEX('Input Data'!$E$19:$E$21,'Input Data'!$D$1)*('Input Data'!P26*'Input Data'!P5*'Input Data'!P6*'Input Data'!P7) -> 42733537
K8: =SUM(K6:K7) -> 56448000 | L8: =SUM(L6:L7) -> 64610381 | M8: =SUM(M6:M7) -> 73655834 | N8: =SUM(N6:N7) -> 83967651 | O8: =SUM(O6:O7) -> 95723122
C10: Credit Sales | K10: =K8*'Input Data'!$E$11 -> 0 | L10: =L8*'Input Data'!$E$11 -> 0 | M10: =M8*'Input Data'!$E$11 -> 0 | N10: =N8*'Input Data'!$E$11 -> 0 | O10: =O8*'Input Data'!$E$11 -> 0
C11: Cash Sales | K11: =K8-K10 -> 56448000 | L11: =L8-L10 -> 64610381 | M11: =M8-M10 -> 73655834 | N11: =N8-N10 -> 83967651 | O11: =O8-O10 -> 95723122
B13: Cost Of Sales
C15: Direct Costs | K15: =SUM('Input Data'!L30:L32)*Workings!K8 -> 14112000 | L15: =SUM('Input Data'!M30:M32)*Workings!L8 -> 16152595 | M15: =SUM('Input Data'!N30:N32)*Workings!M8 -> 18413959 | N15: =SUM('Input Data'!O30:O32)*Workings!N8 -> 20991913 | O15: =SUM('Input Data'!P30:P32)*Workings!O8 -> 23930781
C16: Overhead | K16: ='Input Data'!L34*Workings!K8 -> 2822400 | L16: ='Input Data'!M34*Workings!L8 -> 3230519 | M16: ='Input Data'!N34*Workings!M8 -> 3682791.7 | N16: ='Input Data'!O34*Workings!N8 -> 4198382.5 | O16: ='Input Data'!P34*Workings!O8 -> 4786156.1
K17: =SUM(K15:K16) -> 16934400 | L17: =SUM(L15:L16) -> 19383114 | M17: =SUM(M15:M16) -> 22096750 | N17: =SUM(N15:N16) -> 25190295 | O17: =SUM(O15:O16) -> 28716937
C19: Credit Purchase | K19: ='Input Data'!$E$13*Workings!K15 -> 2822400 | L19: ='Input Data'!$E$13*Workings!L15 -> 3230519 | M19: ='Input Data'!$E$13*Workings!M15 -> 3682791.7 | N19: ='Input Data'!$E$13*Workings!N15 -> 4198382.5 | O19: ='Input Data'!$E$13*Workings!O15 -> 4786156.1
C20: Closing Inventory | K20: =K17*'Input Data'!$E$12 -> 5927040 | L20: =L17*'Input Data'!$E$12 -> 6784090 | M20: =M17*'Input Data'!$E$12 -> 7733862.6 | N20: =N17*'Input Data'!$E$12 -> 8816603.3 | O20: =O17*'Input Data'!$E$12 -> 10050928
B22: Selling General And Admin Exp (SG&A)
C23: Staff Cost
D24: Manager | K24: ='Input Data'!L46*'Input Data'!L55*'Input Data'!$L$7 -> 1800000 | L24: ='Input Data'!M46*'Input Data'!M55*'Input Data'!$L$7 -> 1800000 | M24: ='Input Data'!N46*'Input Data'!N55*'Input Data'!$L$7 -> 1800000 | N24: ='Input Data'!O46*'Input Data'!O55*'Input Data'!$L$7 -> 1800000 | O24: ='Input Data'!P46*'Input Data'!P55*'Input Data'!$L$7 -> 1800000
D25: Head Chef | K25: ='Input Data'!L47*'Input Data'!L56*'Input Data'!$L$7 -> 600000 | L25: ='Input Data'!M47*'Input Data'!M56*'Input Data'!$L$7 -> 600000 | M25: ='Input Data'!N47*'Input Data'!N56*'Input Data'!$L$7 -> 600000 | N25: ='Input Data'!O47*'Input Data'!O56*'Input Data'!$L$7 -> 600000 | O25: ='Input Data'!P47*'Input Data'!P56*'Input Data'!$L$7 -> 600000
D26: Cook | K26: ='Input Data'!L48*'Input Data'!L57*'Input Data'!$L$7 -> 600000 | L26: ='Input Data'!M48*'Input Data'!M57*'Input Data'!$L$7 -> 600000 | M26: ='Input Data'!N48*'Input Data'!N57*'Input Data'!$L$7 -> 600000 | N26: ='Input Data'!O48*'Input Data'!O57*'Input Data'!$L$7 -> 600000 | O26: ='Input Data'!P48*'Input Data'!P57*'Input Data'!$L$7 -> 600000
D27: Kitchen Assistant | K27: ='Input Data'!L49*'Input Data'!L58*'Input Data'!$L$7 -> 420000 | L27: ='Input Data'!M49*'Input Data'!M58*'Input Data'!$L$7 -> 420000 | M27: ='Input Data'!N49*'Input Data'!N58*'Input Data'!$L$7 -> 420000 | N27: ='Input Data'!O49*'Input Data'!O58*'Input Data'!$L$7 -> 420000 | O27: ='Input Data'!P49*'Input Data'!P58*'Input Data'!$L$7 -> 420000
D28: Waiters/waitress | K28: ='Input Data'!L50*'Input Data'!L59*'Input Data'!$L$7 -> 900000 | L28: ='Input Data'!M50*'Input Data'!M59*'Input Data'!$L$7 -> 900000 | M28: ='Input Data'!N50*'Input Data'!N59*'Input Data'!$L$7 -> 900000 | N28: ='Input Data'!O50*'Input Data'!O59*'Input Data'!$L$7 -> 900000 | O28: ='Input Data'!P50*'Input Data'!P59*'Input Data'!$L$7 -> 900000
D29: Cashiers | K29: ='Input Data'!L51*'Input Data'!L60*'Input Data'!$L$7 -> 600000 | L29: ='Input Data'!M51*'Input Data'!M60*'Input Data'!$L$7 -> 600000 | M29: ='Input Data'!N51*'Input Data'!N60*'Input Data'!$L$7 -> 600000 | N29: ='Input Data'!O51*'Input Data'!O60*'Input Data'!$L$7 -> 600000 | O29: ='Input Data'!P51*'Input Data'!P60*'Input Data'!$L$7 -> 600000
D30: Bar Staff | K30: ='Input Data'!L52*'Input Data'!L61*'Input Data'!$L$7 -> 360000 | L30: ='Input Data'!M52*'Input Data'!M61*'Input Data'!$L$7 -> 360000 | M30: ='Input Data'!N52*'Input Data'!N61*'Input Data'!$L$7 -> 360000 | N30: ='Input Data'!O52*'Input Data'!O61*'Input Data'!$L$7 -> 360000 | O30: ='Input Data'!P52*'Input Data'!P61*'Input Data'!$L$7 -> 360000
D31: Cleaner | K31: ='Input Data'!L53*'Input Data'!L62*'Input Data'!$L$7 -> 240000 | L31: ='Input Data'!M53*'Input Data'!M62*'Input Data'!$L$7 -> 240000 | M31: ='Input Data'!N53*'Input Data'!N62*'Input Data'!$L$7 -> 240000 | N31: ='Input Data'!O53*'Input Data'!O62*'Input Data'!$L$7 -> 240000 | O31: ='Input Data'!P53*'Input Data'!P62*'Input Data'!$L$7 -> 240000
K32: =SUM(K24:K31) -> 5520000 | L32: =SUM(L24:L31) -> 5520000 | M32: =SUM(M24:M31) -> 5520000 | N32: =SUM(N24:N31) -> 5520000 | O32: =SUM(O24:O31) -> 5520000
C33: Cooking Gas | K33: ='Input Data'!L37*'Input Data'!L7 -> 1800000 | L33: ='Input Data'!M37*'Input Data'!M7 -> 1800000 | M33: ='Input Data'!N37*'Input Data'!N7 -> 1800000 | N33: ='Input Data'!O37*'Input Data'!O7 -> 1800000 | O33: ='Input Data'!P37*'Input Data'!P7 -> 1800000
C34: Marketing and Promotion | K34: ='Input Data'!L38*Workings!K8 -> 564480 | L34: ='Input Data'!M38*Workings!L8 -> 646103.81 | M34: ='Input Data'!N38*Workings!M8 -> 736558.34 | N34: ='Input Data'!O38*Workings!N8 -> 839676.51 | O34: ='Input Data'!P38*Workings!O8 -> 957231.22
C35: Rent | K35: 0 | L35: ='Input Data'!M39 -> 2000000 | M35: ='Input Data'!N39 -> 2000000 | N35: ='Input Data'!O39 -> 2000000 | O35: ='Input Data'!P39 -> 2000000
C36: Transportation | K36: ='Input Data'!L40*'Input Data'!L7 -> 120000 | L36: ='Input Data'!M40*'Input Data'!M7 -> 120000 | M36: ='Input Data'!N40*'Input Data'!N7 -> 120000 | N36: ='Input Data'!O40*'Input Data'!O7 -> 120000 | O36: ='Input Data'!P40*'Input Data'!P7 -> 120000
C37: Legal Fees | K37: ='Input Data'!L41 -> 100000 | L37: ='Input Data'!M41 -> 100000 | M37: ='Input Data'!N41 -> 100000 | N37: ='Input Data'!O41 -> 100000 | O37: ='Input Data'!P41 -> 100000
C38: Fuel/Diesel | K38: =INDEX('Input Data'!$E$19:$E$21,'Input Data'!$D$1)*('Input Data'!L42*'Input Data'!L7) -> 2400000 | L38: =INDEX('Input Data'!$E$19:$E$21,'Input Data'!$D$1)*('Input Data'!M42*'Input Data'!M7) -> 2400000 | M38: =INDEX('Input Data'!$E$19:$E$21,'Input Data'!$D$1)*('Input Data'!N42*'Input Data'!N7) -> 2400000 | N38: =INDEX('Input Data'!$E$19:$E$21,'Input Data'!$D$1)*('Input Data'!O42*'Input Data'!O7) -> 2400000 | O38: =INDEX('Input Data'!$E$19:$E$21,'Input Data'!$D$1)*('Input Data'!P42*'Input Data'!P7) -> 2400000
C39: Others | K39: ='Input Data'!L43*'Input Data'!L7 -> 1800000 | L39: ='Input Data'!M43*'Input Data'!M7 -> 1800000 | M39: ='Input Data'!N43*'Input Data'!N7 -> 1800000 | N39: ='Input Data'!O43*'Input Data'!O7 -> 1800000 | O39: ='Input Data'!P43*'Input Data'!P7 -> 1800000
C40: Pre-Operational Expenses | K40: ='Input Data'!L115 -> 2025000 | L40: ='Input Data'!H115 -> 0 | M40: ='Input Data'!I115 -> 0 | N40: ='Input Data'!J115 -> 0 | O40: ='Input Data'!K115 -> 0
K41: =SUM(K32:K39) -> 12304480 | L41: =SUM(L32:L39) -> 14386104 | M41: =SUM(M32:M39) -> 14476558 | N41: =SUM(N32:N39) -> 14579677 | O41: =SUM(O32:O39) -> 14697231
B43: Non-Current Asset
C44: Acquisition | G44: USL | H44: Salvage Value
D45: Equipments
E46: Diesel Genenerator | G46: 5 | H46: 200000 | K46: ='Input Data'!L72*'Input Data'!L71 -> 2000000 | L46: ='Input Data'!M72*'Input Data'!M71 -> 0 | M46: ='Input Data'!N72*'Input Data'!N71 -> 0 | N46: ='Input Data'!O72*'Input Data'!O71 -> 850000 | O46: ='Input Data'!P72*'Input Data'!P71 -> 0
E47: Backup Genenerator | G47: 5 | H47: 30000 | K47: ='Input Data'!L78*'Input Data'!L77 -> 300000 | L47: ='Input Data'!M78*'Input Data'!M77 -> 0 | M47: ='Input Data'!N78*'Input Data'!N77 -> 0 | N47: ='Input Data'!O78*'Input Data'!O77 -> 0 | O47: ='Input Data'!P78*'Input Data'!P77 -> 0
...

Sheet Income Statement
A1: ent | B1: Scenario: | H1: The Peak&Light Restaurant | L1: Last Updated: | M1: 26/03/2025
D2: INCOME STATEMENT
H3: 2024 | I3: =H3+1 -> 2025 | J3: =I3+1 -> 2026 | K3: =J3+1 -> 2027 | L3: =K3+1 -> 2028 | M3: =L3+1 -> 2029
B4: Revenue | I4: =Workings!K8 -> 56448000 | J4: =Workings!L8 -> 64610381 | K4: =Workings!M8 -> 73655834 | L4: =Workings!N8 -> 83967651 | M4: =Workings!O8 -> 95723122
B6: Cost Of Sales | I6: =-Workings!K17 -> -16934400 | J6: =-Workings!L17 -> -19383114 | K6: =-Workings!M17 -> -22096750 | L6: =-Workings!N17 -> -25190295 | M6: =-Workings!O17 -> -28716937
B8: Gross Profit | I8: =SUM(I4:I6) -> 39513600 | J8: =SUM(J4:J6) -> 45227267 | K8: =SUM(K4:K6) -> 51559084 | L8: =SUM(L4:L6) -> 58777356 | M8: =SUM(M4:M6) -> 67006185
B10: SG&A | I10: =-Workings!K41 -> -12304480 | J10: =-Workings!L41 -> -14386104 | K10: =-Workings!M41 -> -14476558 | L10: =-Workings!N41 -> -14579677 | M10: =-Workings!O41 -> -14697231
B12: Operating Profit (EBITDA) | I12: =I8+I10 -> 27209120 | J12: =J8+J10 -> 30841163 | K12: =K8+K10 -> 37082526 | L12: =L8+L10 -> 44197679 | M12: =M8+M10 -> 52308954
B14: Depreciation & Amortization | I14: =-Workings!K63 -> -2104800 | J14: =-Workings!L63 -> -2104800 | K14: =-Workings!M63 -> -2104800 | L14: =-Workings!N63 -> -2274800 | M14: =-Workings!O63 -> -2274800
B16: Earnings Before Interest & Tax (EBIT) | I16: =I12+I14 -> 25104320 | J16: =J12+J14 -> 28736363 | K16: =K12+K14 -> 34977726 | L16: =L12+L14 -> 41922879 | M16: =M12+M14 -> 50034154
B18: NET Profit | I18: =I16 -> 25104320 | J18: =J16 -> 28736363 | K18: =K16 -> 34977726 | L18: =L16 -> 41922879 | M18: =M16 -> 50034154
B20: Dividend | I20: =-Workings!K100 -> -6276080 | J20: =-Workings!L100 -> -7184090.7 | K20: =-Workings!M100 -> -8744431.4 | L20: =-Workings!N100 -> -10480720 | M20: =-Workings!O100 -> -12508539
B22: Retained Earnings | I22: =I18+I20 -> 18828240 | J22: =J18+J20 -> 21552272 | K22: =K18+K20 -> 26233294 | L22: =L18+L20 -> 31442159 | M22: =M18+M20 -> 37525616
B24: Cummulative Retained Earnings | I24: =H24+I22 -> 18828240 | J24: =I24+J22 -> 40380512 | K24: =J24+K22 -> 66613806 | L24: =K24+L22 -> 98055966 | M24: =L24+M22 -> 1.3558158e+08

Sheet Balance Sheet
B1: Scenario: | J1: The Peak&Light Restaurant | N1: Last Updated: | O1: 26/03/2025
D2: BALANCE SHEET
J3: 2024 | K3: =J3+1 -> 2025 | L3: =K3+1 -> 2026 | M3: =L3+1 -> 2027 | N3: =M3+1 -> 2028 | O3: =N3+1 -> 2029
C4: Assets
D5: Non-Current Assets
D6: Property,Plant And Equipments
E7: Cost | K7: =Workings!K77 -> 10000000 | L7: =Workings!L77 -> 10000000 | M7: =Workings!M77 -> 10000000 | N7: =Workings!N77 -> 10850000 | O7: =Workings!O77 -> 10850000
E8: Accumulated Depreciatoin | K8: =Workings!K78 -> -2104800 | L8: =Workings!L78 -> -4209600 | M8: =Workings!M78 -> -6314400 | N8: =Workings!N78 -> -8589200 | O8: =Workings!O78 -> -10864000
E9: Net Book Value | K9: =K7+K8 -> 7895200 | L9: =L7+L8 -> 5790400 | M9: =M7+M8 -> 3685600 | N9: =N7+N8 -> 2260800 | O9: =O7+O8 -> -14000
D11: Current Assets
E12: Inventory | K12: =Workings!K20 -> 5927040 | L12: =Workings!L20 -> 6784090 | M12: =Workings!M20 -> 7733862.6 | N12: =Workings!N20 -> 8816603.3 | O12: =Workings!O20 -> 10050928
E13: Cash & Cash Equivalents | K13: =Cashflow!J30 -> 29054973 | L13: =Cashflow!K30 -> 52797016 | M13: =Cashflow!L30 -> 81783368 | N13: =Cashflow!M30 -> 1.1534684e+08 | O13: =Cashflow!N30 -> 1.5598973e+08
D14: Total Current Assets | K14: =SUM(K12:K13) -> 34982013 | L14: =SUM(L12:L13) -> 59581106 | M14: =SUM(M12:M13) -> 89517230 | N14: =SUM(N12:N13) -> 1.2416344e+08 | O14: =SUM(O12:O13) -> 1.6604066e+08
D16: TOTAL ASSETS | K16: =K9+K14 -> 42877213 | L16: =L9+L14 -> 65371506 | M16: =M9+M14 -> 93202830 | N16: =N9+N14 -> 1.2642424e+08 | O16: =O9+O14 -> 1.6602666e+08
C18: Equity
E19: Ordinary Shareholders Equity | K19: =Workings!$K$90 -> 17537693 | L19: =Workings!$K$90 -> 17537693 | M19: =Workings!$K$90 -> 17537693 | N19: =Workings!$K$90 -> 17537693 | O19: =Workings!$K$90 -> 17537693
E20: Cummulative Retained Earnigns | K20: ='Income Statement'!I24 -> 18828240 | L20: ='Income Statement'!J24 -> 40380512 | M20: ='Income Statement'!K24 -> 66613806 | N20: ='Income Statement'!L24 -> 98055966 | O20: ='Income Statement'!M24 -> 1.3558158e+08
D21: TOTAL EQUITY | K21: =SUM(K19:K20) -> 36365933 | L21: =SUM(L19:L20) -> 57918205 | M21: =SUM(M19:M20) -> 84151500 | N21: =SUM(N19:N20) -> 1.1559366e+08 | O21: =SUM(O19:O20) -> 1.5311927e+08
C23: Liabilities
D24: Current Liabilities
E25: Account Payables | K25: =Workings!K95 -> 235200 | L25: =Workings!L95 -> 269209.92 | M25: =Workings!M95 -> 306899.31 | N25: =Workings!N95 -> 349865.21 | O25: =Workings!O95 -> 398846.34
E26: Dividend Payable | K26: =Workings!K100 -> 6276080 | L26: =Workings!L100 -> 7184090.7 | M26: =Workings!M100 -> 8744431.4 | N26: =Workings!N100 -> 10480720 | O26: =Workings!O100 -> 12508539
D28: Total Current Liabilities | K28: =SUM(K25:K27) -> 6511280 | L28: =SUM(L25:L27) -> 7453300.6 | M28: =SUM(M25:M27) -> 9051330.7 | N28: =SUM(N25:N27) -> 10830585 | O28: =SUM(O25:O27) -> 12907385
D30: Total Liabilities | K30: =K28 -> 6511280 | L30: =L28 -> 7453300.6 | M30: =M28 -> 9051330.7 | N30: =N28 -> 10830585 | O30: =O28 -> 12907385
C32: Total Equities And Liabilities | K32: =K30+K21 -> 42877213 | L32: =L30+L21 -> 65371506 | M32: =M30+M21 -> 93202830 | N32: =N30+N21 -> 1.2642424e+08 | O32: =O30+O21 -> 1.6602666e+08

Sheet Cashflow
B1: Scenario: | I1: The Peak&Light Restaurant | M1: Last Updated: | N1: 26/03/2025
D2: CASHFLOW STATEMENT
I3: 2024 | J3: =I3+1 -> 2025 | K3: =J3+1 -> 2026 | L3: =K3+1 -> 2027 | M3: =L3+1 -> 2028 | N3: =M3+1 -> 2029
C4: Operating Activities
D5: Net Profit (Profit After Tax) | J5: ='Income Statement'!I18 -> 25104320 | K5: ='Income Statement'!J18 -> 28736363 | L5: ='Income Statement'!K18 -> 34977726 | M5: ='Income Statement'!L18 -> 41922879 | N5: ='Income Statement'!M18 -> 50034154
D6: Adjustments:
E7: Depreciation | J7: =-'Income Statement'!I14 -> 2104800 | K7: =-'Income Statement'!J14 -> 2104800 | L7: =-'Income Statement'!K14 -> 2104800 | M7: =-'Income Statement'!L14 -> 2274800 | N7: =-'Income Statement'!M14 -> 2274800
C8: Cashflow Before Working Adj. | J8: =SUM(J5:J7) -> 27209120 | K8: =SUM(K5:K7) -> 30841163 | L8: =SUM(L5:L7) -> 37082526 | M8: =SUM(M5:M7) -> 44197679 | N8: =SUM(N5:N7) -> 52308954
D9: Working Capital Adjustment
E10: Inventory | J10: ='Balance Sheet'!J12-'Balance Sheet'!K12 -> -5927040 | K10: ='Balance Sheet'!K12-'Balance Sheet'!L12 -> -857049.98 | L10: ='Balance Sheet'!L12-'Balance Sheet'!M12 -> -949772.6 | M10: ='Balance Sheet'!M12-'Balance Sheet'!N12 -> -1082740.8 | N10: ='Balance Sheet'!N12-'Balance Sheet'!O12 -> -1234324.5
E11: Payables | J11: ='Balance Sheet'!K25-'Balance Sheet'!J25 -> 235200 | K11: ='Balance Sheet'!L25-'Balance Sheet'!K25 -> 34009.92 | L11: ='Balance Sheet'!M25-'Balance Sheet'!L25 -> 37689.389 | M11: ='Balance Sheet'!N25-'Balance Sheet'!M25 -> 42965.903 | N11: ='Balance Sheet'!O25-'Balance Sheet'!N25 -> 48981.13
C12: Cashflow After Working Capital Adj. | J12: =SUM(J8:J11) -> 21517280 | K12: =SUM(K8:K11) -> 30018123 | L12: =SUM(L8:L11) -> 36170442 | M12: =SUM(M8:M11) -> 43157904 | N12: =SUM(N8:N11) -> 51123611
C14: Net Cashflow from Operating Activities | J14: =J12 -> 21517280 | K14: =K12 -> 30018123 | L14: =L12 -> 36170442 | M14: =M12 -> 43157904 | N14: =N12 -> 51123611
C16: Investing Activities
D17: PPE | J17: =-Workings!K53 -> -10000000 | K17: =-Workings!L53 -> 0 | L17: =-Workings!M53 -> 0 | M17: =-Workings!N53 -> -850000 | N17: =-Workings!O53 -> 0
C19: Net Cashflow From Investing Activities | J19: =SUM(J17:J18) -> -10000000 | K19: =SUM(K17:K18) -> 0 | L19: =SUM(L17:L18) -> 0 | M19: =SUM(M17:M18) -> -850000 | N19: =SUM(N17:N18) -> 0
C21: Financing Activities
D22: Shareholders Equity | J22: =Workings!K90 -> 17537693 | K22: =Workings!L90 -> 0 | L22: =Workings!M90 -> 0 | M22: =Workings!N90 -> 0 | N22: =Workings!O90 -> 0
D23: Proceed From Debt | J23: =Workings!K91 -> 0
D24: Dividend | J24: ='Income Statement'!H20 -> 0 | K24: ='Income Statement'!I20 -> -6276080 | L24: ='Income Statement'!J20 -> -7184090.7 | M24: ='Income Statement'!K20 -> -8744431.4 | N24: ='Income Statement'!L20 -> -10480720
C26: Net Cashflow From Financing Activities | J26: =SUM(J22:J25) -> 17537693 | K26: =SUM(K22:K25) -> -6276080 | L26: =SUM(L22:L25) -> -7184090.7 | M26: =SUM(M22:M25) -> -8744431.4 | N26: =SUM(N22:N25) -> -10480720
C28: Net Changes | J28: =J14+J19+J26 -> 29054973 | K28: =K14+K19+K26 -> 23742043 | L28: =L14+L19+L26 -> 28986352 | M28: =M14+M19+M26 -> 33563473 | N28: =N14+N19+N26 -> 40642891
C29: Opening Balance | J29: =I30 -> 0 | K29: =J30 -> 29054973 | L29: =K30 -> 52797016 | M29: =L30 -> 81783368 | N29: =M30 -> 1.1534684e+08
C30: Closing Balance | J30: =J28+J29 -> 29054973 | K30: =K28+K29 -> 52797016 | L30: =L28+L29 -> 81783368 | M30: =M28+M29 -> 1.1534684e+08 | N30: =N28+N29 -> 1.5598973e+08

Sheet Valuation
B1: Scenario: | I1: The Peak&Light Restaurant | L1: Last Updated: | M1: 26/03/2025
D2: VALUATION
H3: 2024 | I3: 1 | J3: 2 | K3: 3 | L3: 4 | M3: 5
B4: Free Cashflow To Firm (FCF)
B5: (Unlevered Free Cash Flow)
E6: Net Income | I6: ='Income Statement'!I18 -> 25104320 | J6: ='Income Statement'!J18 -> 28736363 | K6: ='Income Statement'!K18 -> 34977726 | L6: ='Income Statement'!L18 -> 41922879 | M6: ='Income Statement'!M18 -> 50034154
D7: Add:Non-Cash Items | F7: Dep. & Amort. | I7: =-'Income Statement'!I14 -> 2104800 | J7: =-'Income Statement'!J14 -> 2104800 | K7: =-'Income Statement'!K14 -> 2104800 | L7: =-'Income Statement'!L14 -> 2274800 | M7: =-'Income Statement'!M14 -> 2274800
D8: Less: Changes in Working Capital | I8: =Cashflow!J10+Cashflow!J11 -> -5691840 | J8: =Cashflow!K10+Cashflow!K11 -> -823040.06 | K8: =Cashflow!L10+Cashflow!L11 -> -912083.21 | L8: =Cashflow!M10+Cashflow!M11 -> -1039774.9 | M8: =Cashflow!N10+Cashflow!N11 -> -1185343.3
D9: Less: CAPEX | I9: =Workings!K53 -> 10000000 | J9: =Workings!L53 -> 0 | K9: =Workings!M53 -> 0 | L9: =Workings!N53 -> 850000 | M9: =Workings!O53 -> 0
C11: FCFF | I11: =SUM(I6:I10) -> 31517280 | J11: =SUM(J6:J10) -> 30018123 | K11: =SUM(K6:K10) -> 36170442 | L11: =SUM(L6:L10) -> 44007904 | M11: =SUM(M6:M10) -> 51123611
C12: Terminal Value | E12: (FCFF YR5 *(1+Growth Rate) | M12: =(M11*(1+I47))/I44-I47 -> 2.8304034e+08
E13: WACC-Growth Rate
E14: Total FCFF | I14: =I11+I12 -> 31517280 | J14: =J11+J12 -> 30018123 | K14: =K11+K12 -> 36170442 | L14: =L11+L12 -> 44007904 | M14: =M11+M12 -> 3.3416395e+08
C17: Discounting Factor | E17: (1+wacc)^-n | I17: =(1+$I$44)^-I3 -> 0.84206344 | J17: =(1+$I$44)^-J3 -> 0.70907084 | K17: =(1+$I$44)^-K3 -> 0.59708263 | L17: =(1+$I$44)^-L3 -> 0.50278145 | M17: =(1+$I$44)^-M3 -> 0.42337388
E19: Present Value | I19: =I14*I17 -> 26539549 | J19: =J14*J17 -> 21284975 | K19: =K14*K17 -> 21596743 | L19: =L14*L17 -> 22126358 | M19: =M14*M17 -> 1.4147629e+08
E21: Enterprise Valuation | I21: =SUM(I19:M19) -> 2.3302391e+08
B23: Free Cashflow To Equity (FCFE)
B24: (Unlevered Free Cash Flow)
E25: Net Income | I25: ='Income Statement'!I18 -> 25104320 | J25: ='Income Statement'!J18 -> 28736363 | K25: ='Income Statement'!K18 -> 34977726 | L25: ='Income Statement'!L18 -> 41922879 | M25: ='Income Statement'!M18 -> 50034154
D26: Add:Non-Cash Items | F26: Dep. & Amort. | I26: =-'Income Statement'!I14 -> 2104800 | J26: =-'Income Statement'!J14 -> 2104800 | K26: =-'Income Statement'!K14 -> 2104800 | L26: =-'Income Statement'!L14 -> 2274800 | M26: =-'Income Statement'!M14 -> 2274800
D27: Less: Changes in Working Capital | I27: =Cashflow!J10+Cashflow!J11 -> -5691840 | J27: =Cashflow!K10+Cashflow!K11 -> -823040.06 | K27: =Cashflow!L10+Cashflow!L11 -> -912083.21 | L27: =Cashflow!M10+Cashflow!M11 -> -1039774.9 | M27: =Cashflow!N10+Cashflow!N11 -> -1185343.3
D28: Less: CAPEX | I28: =-Workings!K53 -> -10000000 | J28: =-Workings!L53 -> 0 | K28: =-Workings!M53 -> 0 | L28: =-Workings!N53 -> -850000 | M28: =-Workings!O53 -> 0
C30: FCFE | I30: =SUM(I25:I29) -> 11517280 | J30: =SUM(J25:J29) -> 30018123 | K30: =SUM(K25:K29) -> 36170442 | L30: =SUM(L25:L29) -> 42307904 | M30: =SUM(M25:M29) -> 51123611
C32: Terminal Value | E32: (FCFF YR5 *(1+Growth Rate) | M32: =(M30*(1+I47))/(I46-I47) -> 3.5590722e+08
E33: WACC-Growth Rate
E34: Total FCFE | I34: =I30+I31 -> 11517280 | J34: =J30+J31 -> 30018123 | K34: =K30+K31 -> 36170442 | L34: =L30+L31 -> 42307904 | M34: =M30+M31 -> 51123611
C37: Discounting Factor | E37: (1+Cost Of Equity)^-n | I37: =(1+$I$46)^-I3 -> 0.84206344 | J37: =(1+$I$46)^-J3 -> 0.70907084 | K37: =(1+$I$46)^-K3 -> 0.59708263 | L37: =(1+$I$46)^-L3 -> 0.50278145 | M37: =(1+$I$46)^-M3 -> 0.42337388
E39: Present Value | I39: =I34*I37 -> 9698280.4 | J39: =J34*J37 -> 21284975 | K39: =K34*K37 -> 21596743 | L39: =L34*L37 -> 21271630 | M39: =M34*M37 -> 21644402
E41: Equity Valuation | I41: =SUM(I39:M39) -> 95496030
C44: WACC | I44: =Workings!K104 -> 0.18755898
C46: Cost Of Equity | I46: =Workings!K106 -> 0.18755898
C47: Long Term Growth Rate | I47: ='Input Data'!E15 -> 0.0384

Sheet Financial Ratios
B1: Scenario: | J1: The Peak&Light Restaurant | M1: Last Updated: | N1: 26/03/2025
D2: FINANCIAL RATIOS
I3: 2024 | J3: 1 | K3: 2 | L3: 3 | M3: 4 | N3: 5
C4: Profitability
D5: GP Margin | J5: ='Income Statement'!I8/'Income Statement'!I4 -> 0.7 | K5: ='Income Statement'!J8/'Income Statement'!J4 -> 0.7 | L5: ='Income Statement'!K8/'Income Statement'!K4 -> 0.7 | M5: ='Income Statement'!L8/'Income Statement'!L4 -> 0.7 | N5: ='Income Statement'!M8/'Income Statement'!M4 -> 0.7
D6: OP Margin | J6: ='Income Statement'!I12/'Income Statement'!I4 -> 0.48202098 | K6: ='Income Statement'!J12/'Income Statement'!J4 -> 0.47734067 | L6: ='Income Statement'!K12/'Income Statement'!K4 -> 0.50345673 | M6: ='Income Statement'!L12/'Income Statement'!L4 -> 0.52636555 | N6: ='Income Statement'!M12/'Income Statement'!M4 -> 0.54646101
D7: Np Margin | J7: ='Income Statement'!I18/'Income Statement'!I4 -> 0.44473356 | K7: ='Income Statement'!J18/'Income Statement'!J4 -> 0.44476387 | L7: ='Income Statement'!K18/'Income Statement'!K4 -> 0.47488058 | M7: ='Income Statement'!L18/'Income Statement'!L4 -> 0.49927417 | N7: ='Income Statement'!M18/'Income Statement'!M4 -> 0.52269664
D9: ROCE | J9: ='Income Statement'!I18/'Balance Sheet'!K21 -> 0.69032519 | K9: ='Income Statement'!J18/'Balance Sheet'!L21 -> 0.49615423 | L9: ='Income Statement'!K18/'Balance Sheet'!M21 -> 0.41565184 | M9: ='Income Statement'!L18/'Balance Sheet'!N21 -> 0.36267456 | N9: ='Income Statement'!M18/'Balance Sheet'!O21 -> 0.32676588
D10: ROA | J10: ='Income Statement'!I18/'Balance Sheet'!K16 -> 0.58549327 | K10: ='Income Statement'!J18/'Balance Sheet'!L16 -> 0.43958545 | L10: ='Income Statement'!K18/'Balance Sheet'!M16 -> 0.37528609 | M10: ='Income Statement'!L18/'Balance Sheet'!N16 -> 0.33160474 | N10: ='Income Statement'!M18/'Balance Sheet'!O16 -> 0.30136217
C12: Liquidity
D13: Current Ratio | J13: ='Balance Sheet'!K14/'Balance Sheet'!K28 -> 5.3725248 | K13: ='Balance Sheet'!L14/'Balance Sheet'!L28 -> 7.9939223 | L13: ='Balance Sheet'!M14/'Balance Sheet'!M28 -> 9.8899525 | M13: ='Balance Sheet'!N14/'Balance Sheet'!N28 -> 11.464149 | N13: ='Balance Sheet'!O14/'Balance Sheet'!O28 -> 12.864005
D14: Quick (Acid Test) Ratio | J14: =('Balance Sheet'!K14-'Balance Sheet'!K12)/'Balance Sheet'!K28 -> 4.4622522 | K14: =('Balance Sheet'!L14-'Balance Sheet'!L12)/'Balance Sheet'!L28 -> 7.0837095 | L14: =('Balance Sheet'!M14-'Balance Sheet'!M12)/'Balance Sheet'!M28 -> 9.0355076 | M14: =('Balance Sheet'!N14-'Balance Sheet'!N12)/'Balance Sheet'!N28 -> 10.650103 | N14: =('Balance Sheet'!O14-'Balance Sheet'!O12)/'Balance Sheet'!O28 -> 12.085309
D15: Cash Ratio | J15: ='Balance Sheet'!K13/'Balance Sheet'!K28 -> 4.4622522 | K15: ='Balance Sheet'!L13/'Balance Sheet'!L28 -> 7.0837095 | L15: ='Balance Sheet'!M13/'Balance Sheet'!M28 -> 9.0355076 | M15: ='Balance Sheet'!N13/'Balance Sheet'!N28 -> 10.650103 | N15: ='Balance Sheet'!O13/'Balance Sheet'!O28 -> 12.085309
C17: Leverage
D18: Equity Ratio | J18: ='Balance Sheet'!K21/'Balance Sheet'!K16 -> 0.84814125 | K18: ='Balance Sheet'!L21/'Balance Sheet'!L16 -> 0.88598548 | L18: ='Balance Sheet'!M21/'Balance Sheet'!M16 -> 0.90288567 | M18: ='Balance Sheet'!N21/'Balance Sheet'!N16 -> 0.91433142 | N18: ='Balance Sheet'!O21/'Balance Sheet'!O16 -> 0.92225715
C20: Effeciency Ratios
D22: Inventory Turnover Ratio | J22: =-'Income Statement'!I6/(('Balance Sheet'!K12+'Balance Sheet'!J12)/2) -> 5.7142857 | K22: =-'Income Statement'!J6/(('Balance Sheet'!L12+'Balance Sheet'!K12)/2) -> 3.0497862 | L22: =-'Income Statement'!K6/(('Balance Sheet'!M12+'Balance Sheet'!L12)/2) -> 3.0440587 | M22: =-'Income Statement'!L6/(('Balance Sheet'!N12+'Balance Sheet'!M12)/2) -> 3.0440587 | N22: =-'Income Statement'!M6/(('Balance Sheet'!O12+'Balance Sheet'!N12)/2) -> 3.0440587
D23: Day Inventory Outstanding (IR Turnover in Days) | J23: =365/J22 -> 63.875 | K23: =365/K22 -> 119.68052 | L23: =365/L22 -> 119.9057 | M23: =365/M22 -> 119.9057 | N23: =365/N22 -> 119.9057
D25: Account payable Ratio | J25: =Workings!K19/(('Balance Sheet'!K25+'Balance Sheet'!J25)/2) -> 24 | K25: =Workings!L19/(('Balance Sheet'!L25+'Balance Sheet'!K25)/2) -> 12.809102 | L25: =Workings!M19/(('Balance Sheet'!M25+'Balance Sheet'!L25)/2) -> 12.785047 | M25: =Workings!N19/(('Balance Sheet'!N25+'Balance Sheet'!M25)/2) -> 12.785047 | N25: =Workings!O19/(('Balance Sheet'!O25+'Balance Sheet'!N25)/2) -> 12.785047
D26: Days Payable Outstanding ( Ap Turnover in Days) | J26: =365/J25 -> 15.208333 | K26: =365/K25 -> 28.495362 | L26: =365/L25 -> 28.548977 | M26: =365/M25 -> 28.548977 | N26: =365/N25 -> 28.548977
C28: Operating Circle | J28: =J23-J26 -> 48.666667 | K28: =K23-K26 -> 91.185159 | L28: =L23-L26 -> 91.356725 | M28: =M23-M26 -> 91.356725 | N28: =N23-N26 -> 91.356725

Sheet Dataset
B1: Scenario: | G1: The Peak&Light Restaurant | L1: Last Updated: | M1: 26/03/2025
D2: DATASET
C4: Year | D4: Revenue | E4: Cost Of Sales | F4: Gross Profit | G4: OPEX Items | H4: OPEX | I4: Operating Profit | J4: Net Profit | K4: GP Margin | L4: NP Margin | M4: ROCE
C5: 2025 | D5: ='Income Statement'!I4 -> 56448000 | E5: =('Income Statement'!I6)*-1 -> 16934400 | F5: ='Income Statement'!I8 -> 39513600 | I5: ='Income Statement'!I12 -> 27209120 | J5: ='Income Statement'!I18 -> 25104320 | K5: ='Financial Ratios'!J5 -> 0.7 | L5: ='Financial Ratios'!J7 -> 0.44473356 | M5: ='Financial Ratios'!J9 -> 0.69032519
C6: 2026 | D6: ='Income Statement'!J4 -> 64610381 | E6: =('Income Statement'!J6)*-1 -> 19383114 | F6: ='Income Statement'!J8 -> 45227267 | I6: ='Income Statement'!J12 -> 30841163 | J6: ='Income Statement'!J18 -> 28736363 | K6: ='Financial Ratios'!K5 -> 0.7 | L6: ='Financial Ratios'!K7 -> 0.44476387 | M6: ='Financial Ratios'!K9 -> 0.49615423
C7: 2027 | D7: ='Income Statement'!K4 -> 73655834 | E7: =('Income Statement'!K6)*-1 -> 22096750 | F7: ='Income Statement'!K8 -> 51559084 | I7: ='Income Statement'!K12 -> 37082526 | J7: ='Income Statement'!K18 -> 34977726 | K7: ='Financial Ratios'!L5 -> 0.7 | L7: ='Financial Ratios'!L7 -> 0.47488058 | M7: ='Financial Ratios'!L9 -> 0.41565184
C8: 2028 | D8: ='Income Statement'!L4 -> 83967651 | E8: =('Income Statement'!L6)*-1 -> 25190295 | F8: ='Income Statement'!L8 -> 58777356 | I8: ='Income Statement'!L12 -> 44197679 | J8: ='Income Statement'!L18 -> 41922879 | K8: ='Financial Ratios'!M5 -> 0.7 | L8: ='Financial Ratios'!M7 -> 0.49927417 | M8: ='Financial Ratios'!M9 -> 0.36267456
C9: 2029 | D9: ='Income Statement'!M4 -> 95723122 | E9: =('Income Statement'!M6)*-1 -> 28716937 | F9: ='Income Statement'!M8 -> 67006185 | I9: ='Income Statement'!M12 -> 52308954 | J9: ='Income Statement'!M18 -> 50034154 | K9: ='Financial Ratios'!N5 -> 0.7 | L9: ='Financial Ratios'!N7 -> 0.52269664 | M9: ='Financial Ratios'!N9 -> 0.32676588
C10: 2025 | G10: Employee Cost | H10: =Workings!K32 -> 5520000
C11: 2025 | G11: Dep. & Amort | H11: =('Income Statement'!I14)*-1 -> 2104800
C12: 2025 | G12: Other Expenses | H12: =SUM(Workings!K33:K40) -> 8809480
C13: 2026 | G13: Employee Cost | H13: =Workings!L32 -> 5520000
C14: 2026 | G14: Dep. & Amort | H14: =('Income Statement'!J14)*-1 -> 2104800
C15: 2026 | G15: Other Expenses | H15: =SUM(Workings!L34:L40) -> 7066103.8
C16: 2027 | G16: Employee Cost | H16: =Workings!M32 -> 5520000
C17: 2027 | G17: Dep. & Amort | H17: =('Income Statement'!K14)*-1 -> 2104800
C18: 2027 | G18: Other Expenses | H18: =SUM(Workings!M33:M40) -> 8956558.3
C19: 2028 | G19: Employee Cost | H19: =Workings!N32 -> 5520000
C20: 2028 | G20: Dep. & Amort | H20: =('Income Statement'!L14)*-1 -> 2274800
C21: 2028 | G21: Other Expenses | H21: =SUM(Workings!N33:N40) -> 9059676.5
C22: 2029 | G22: Employee Cost | H22: =Workings!O32 -> 5520000
C23: 2029 | G23: Dep. & Amort | H23: =('Income Statement'!M14)*-1 -> 2274800
C24: 2029 | G24: Other Expenses | H24: =SUM(Workings!O33:O40) -> 9177231.2

Sheet Pivot
B3: Row Labels | C3: Sum of Revenue | D3: Sum of Cost Of Sales | E3: Sum of Gross Profit
B4: 2025 | C4: 56448000 | D4: 16934400 | E4: 39513600
B5: 2026 | C5: 64610381 | D5: 19383114 | E5: 45227267
B6: 2027 | C6: 73655834 | D6: 22096750 | E6: 51559084
B7: 2028 | C7: 83967651 | D7: 25190295 | E7: 58777356
B8: 2029 | C8: 95723122 | D8: 28716937 | E8: 67006185
B9: Grand Total | C9: 3.7440499e+08 | D9: 1.123215e+08 | E9: 2.6208349e+08
B12: Row Labels | C12: Sum of OPEX
B13: Dep. & Amort | C13: 10864000
B14: Employee Cost | C14: 27600000
B15: Other Expenses | C15: 43069050
B16: Grand Total | C16: 81533050
B22: Sum of OPEX | C22: Column Labels
B23: Row Labels | C23: Dep. & Amort | D23: Employee Cost | E23: Other Expenses
B24: 2025 | C24: 2104800 | D24: 5520000 | E24: 8809480
B25: 2026 | C25: 2104800 | D25: 5520000 | E25: 7066103.8
B26: 2027 | C26: 2104800 | D26: 5520000 | E26: 8956558.3
B27: 2028 | C27: 2274800 | D27: 5520000 | E27: 9059676.5
B28: 2029 | C28: 2274800 | D28: 5520000 | E28: 9177231.2
B29: Grand Total | C29: 10864000 | D29: 27600000 | E29: 43069050
B32: Row Labels | C32: Average of Revenue | D32: Average of Gross Profit | E32: Average of Net Profit
B33: 2025 | C33: 56448000 | D33: 39513600 | E33: 25104320
B34: 2026 | C34: 64610381 | D34: 45227267 | E34: 28736363
B35: 2027 | C35: 73655834 | D35: 51559084 | E35: 34977726
B36: 2028 | C36: 83967651 | D36: 58777356 | E36: 41922879
B37: 2029 | C37: 95723122 | D37: 67006185 | E37: 50034154 | G37: Revenue | H37: Gross Profit | I37: Net Profit
B38: Grand Total | C38: 74880998 | D38: 52416698 | E38: 36155088 | G38: =GETPIVOTDATA("Average of Revenue",$B$32) -> 74880998 | H38: =GETPIVOTDATA("Average of Gross Profit",$B$32) -> 52416698 | I38: =GETPIVOTDATA("Average of Net Profit",$B$32) -> 36155088
B41: Row Labels | C41: Sum of GP Margin | D41: Sum of NP Margin | E41: Sum of ROCE
B42: 2025 | C42: 0.7 | D42: 0.44473356 | E42: 0.69032519
B43: 2026 | C43: 0.7 | D43: 0.44476387 | E43: 0.49615423
B44: 2027 | C44: 0.7 | D44: 0.47488058 | E44: 0.41565184
B45: 2028 | C45: 0.7 | D45: 0.49927417 | E45: 0.36267456
B46: 2029 | C46: 0.7 | D46: 0.52269664 | E46: 0.32676588
B47: Grand Total | C47: 3.5 | D47: 2.3863488 | E47: 2.2915717
